Workbook

Sheet Landing_Page
B2: ="PCGH Annual QMR — "&Controls!$B$8&" — FY "&Controls!$B$5 -> PCGH Annual QMR — PC Ghana — FY 2026
B3: Quarterly management reporting command centre — select the quarter on Controls; everything below updates live.
B5: Reporting period end | D5: Quarter | F5: Entity | H5: Approval status | J5: Source refresh date | L5: Version
B6: =Controls!$B$4 -> 46203 | D6: =Controls!$B$6 -> Q2 | F6: =Controls!$B$7 -> PCGH | H6: =Controls!$B$23 -> Draft | J6: =Controls!$B$26 -> 46203 | L6: =Controls!$B$25 -> v2.5
B8: KEY INDICATORS — SELECTED QUARTER (GHS '000)
B9: Income forecast FY | D9: Secured net YTD | F9: WIP YTD | H9: Fixed costs YTD | J9: Surplus FY forecast | L9: Working capital
B10: =QMR_Report!$C$29/1000 -> 18393.381 | D10: =QMR_Report!$D$29/1000 -> 14867.848 | F10: =QMR_Report!$E$29/1000 -> 8798.0185 | H10: =QMR_Report!$F$47/1000 -> 5801.7136 | J10: =QMR_Report!$C$56/1000 -> 4619.009 | L10: =IFERROR(--INDEX(Balance_Sheet!$C$34:$F$34,1,VALUE(MID(Controls!$B$6,2,1))),0)/1000 -> 5711.2079
B12: Months cost cover | D12: Data quality
B13: =IFERROR(--INDEX(Balance_Sheet!$C$36:$F$36,1,VALUE(MID(Controls!$B$6,2,1))),0) -> 5.7737739 | D13: =Checks!$B$3 -> PASS WITH REVIEW
B15: ALERTS AND DATA STATUS
B16: Failed checks | D16: =COUNTIF(Checks!$F$8:$F$41,"FAIL") -> 0
B17: Review items | D17: =COUNTIF(Checks!$F$8:$F$41,"REVIEW") -> 5
B18: Top issue 1 | D18: =IFERROR(INDEX(Checks!$A:$A,_xlfn.AGGREGATE(15,6,ROW(Checks!$F$8:$F$41)/((Checks!$F$8:$F$41="FAIL")+(Checks!$F$8:$F$41="REVIEW")>0),1)),"—") -> Project forecast exceptions
B19: Top issue 2 | D19: =IFERROR(INDEX(Checks!$A:$A,_xlfn.AGGREGATE(15,6,ROW(Checks!$F$8:$F$41)/((Checks!$F$8:$F$41="FAIL")+(Checks!$F$8:$F$41="REVIEW")>0),2)),"—") -> Commodity/Client residual (values not in lists)
B20: Top issue 3 | D20: =IFERROR(INDEX(Checks!$A:$A,_xlfn.AGGREGATE(15,6,ROW(Checks!$F$8:$F$41)/((Checks!$F$8:$F$41="FAIL")+(Checks!$F$8:$F$41="REVIEW")>0),3)),"—") -> PA ↔ TB nominal-code reconciliation (Project Activity vs Trial Balance)
B21: Quarter data loaded | D21: =Controls!$F$5&": "&Controls!$H$5 -> Q1: DATA LOADED | F21: =Controls!$F$6&": "&Controls!$H$6 -> Q2: DATA LOADED | H21: =Controls!$F$7&": "&Controls!$H$7 -> Q3: NOT LOADED | J21: =Controls!$F$8&": "&Controls!$H$8 -> Q4: NOT LOADED
B23: MANAGEMENT ACTION POINTS (open items from Mgmt_Commentary)
B24: 1. | C24: =IFERROR(INDEX(Mgmt_Commentary!$F:$F,_xlfn.AGGREGATE(15,6,ROW(Mgmt_Commentary!$I$5:$I$34)/(Mgmt_Commentary!$I$5:$I$34="Open"),1))&" ["&INDEX(Mgmt_Commentary!$G:$G,_xlfn.AGGREGATE(15,6,ROW(Mgmt_Commentary!$I$5:$I$34)/(Mgmt_Commentary!$I$5:$I$34="Open"),1))&" — due "&INDEX(Mgmt_Commentary!$H:$H,_xlfn.AGGREGATE(15,6,ROW(Mgmt_Commentary!$I$5:$I$34)/(Mgmt_Commentary!$I$5:$I$34="Open"),1))&"]","—") -> Confirm monthly phasing with budget holders; replace even phasing if a profile is approved [Finance — due 2026-08-15]
B25: 2. | C25: =IFERROR(INDEX(Mgmt_Commentary!$F:$F,_xlfn.AGGREGATE(15,6,ROW(Mgmt_Commentary!$I$5:$I$34)/(Mgmt_Commentary!$I$5:$I$34="Open"),2))&" ["&INDEX(Mgmt_Commentary!$G:$G,_xlfn.AGGREGATE(15,6,ROW(Mgmt_Commentary!$I$5:$I$34)/(Mgmt_Commentary!$I$5:$I$34="Open"),2))&" — due "&INDEX(Mgmt_Commentary!$H:$H,_xlfn.AGGREGATE(15,6,ROW(Mgmt_Commentary!$I$5:$I$34)/(Mgmt_Commentary!$I$5:$I$34="Open"),2))&"]","—") -> PM to true-up gross forecast in MM_Income for completed projects [Project Leads — due 2026-07-31]
B26: 3. | C26: =IFERROR(INDEX(Mgmt_Commentary!$F:$F,_xlfn.AGGREGATE(15,6,ROW(Mgmt_Commentary!$I$5:$I$34)/(Mgmt_Commentary!$I$5:$I$34="Open"),3))&" ["&INDEX(Mgmt_Commentary!$G:$G,_xlfn.AGGREGATE(15,6,ROW(Mgmt_Commentary!$I$5:$I$34)/(Mgmt_Commentary!$I$5:$I$34="Open"),3))&" — due "&INDEX(Mgmt_Commentary!$H:$H,_xlfn.AGGREGATE(15,6,ROW(Mgmt_Commentary!$I$5:$I$34)/(Mgmt_Commentary!$I$5:$I$34="Open"),3))&"]","—") -> Provide portfolio split on QMR_Inputs block 1 [Finance Lead — due 2026-07-31]
B28: NAVIGATION
B29: DASHBOARDS | E29: REPORTS | H29: DATA INPUTS | K29: MAPPINGS & GOVERNANCE
B30: =HYPERLINK("#'QMR_Dashboard'!A1","QMR Dashboard") -> QMR Dashboard | E30: =HYPERLINK("#'QMR_Report'!A1","QMR Report") -> QMR Report | H30: =HYPERLINK("#'Controls'!A1","Controls") -> Controls | K30: =HYPERLINK("#'MM_Income'!A1","MM Income") -> MM Income
B31: =HYPERLINK("#'Project_Output'!A1","Project Income") -> Project Income | E31: =HYPERLINK("#'Slide_Pack'!A1","Slide Pack") -> Slide Pack | H31: =HYPERLINK("#'Project_Activity'!A1","Project Activity") -> Project Activity | K31: =HYPERLINK("#'MM_FixedCost'!A1","MM Fixed Cost") -> MM Fixed Cost
B32: =HYPERLINK("#'FixedCost_Output'!A1","Fixed Costs") -> Fixed Costs | E32: =HYPERLINK("#'FC_Budget_Vrs_Actual'!A1","FC Budget Vrs Actual") -> FC Budget Vrs Actual | H32: =HYPERLINK("#'Project_Forecast'!A1","Project Forecast") -> Project Forecast | K32: =HYPERLINK("#'Master_Mappings'!A1","Master Mappings") -> Master Mappings
B33: =HYPERLINK("#'Balance_Sheet'!A1","Balance Sheet") -> Balance Sheet | E33: =HYPERLINK("#'Annual_Summary'!A1","Annual Summary") -> Annual Summary | H33: =HYPERLINK("#'Nominal_Activity'!A1","Nominal Activity") -> Nominal Activity | K33: =HYPERLINK("#'Checks'!A1","Checks & Controls") -> Checks & Controls
B34: =HYPERLINK("#'TB_Review'!A1","Trial Balance Review") -> Trial Balance Review | E34: =HYPERLINK("#'Consolidation'!A1","Consolidation") -> Consolidation | H34: =HYPERLINK("#'Trial_Balance'!A1","Trial Balance") -> Trial Balance | K34: =HYPERLINK("#'Mgmt_Commentary'!A1","Commentary & Actions") -> Commentary & Actions
H35: =HYPERLINK("#'QMR_Inputs'!A1","QMR Inputs") -> QMR Inputs | K35: =HYPERLINK("#'Instructions'!A1","Instructions") -> Instructions

Sheet Controls
A1: PCGH Annual QMR — Controls, Reporting Calendar and Assumptions
A3: Control | B3: Value | C3: Units | D3: Source / Note | F3: Annual Reporting Calendar
A4: Reporting period end | B4: 46203 | C4: Date | D4: Q1 2026 source packs | F4: Quarter | G4: Period_End | H4: Data_Status
A5: Fiscal year | B5: =YEAR(B4) -> 2026 | C5: Year | D5: Calendar year | F5: Q1 | G5: 46112 | H5: =IF(COUNTIF(Project_Forecast!$B$2:$B$4993,$B$5&"-"&F5)+COUNTIF(Nominal_Activity!$B$2:$B$5000,$B$5&"-"&F5)+COUNTIF(Trial_Balance!$B$2:$B$4995,$B$5&"-"&F5)>0,"DATA LOADED","NOT LOADED") -> DATA LOADED
A6: Quarter | B6: ="Q"&ROUNDUP(MONTH(B4)/3,0) -> Q2 | C6: Quarter | D6: Calendar quarter | F6: Q2 | G6: 46203 | H6: =IF(COUNTIF(Project_Forecast!$B$2:$B$4993,$B$5&"-"&F6)+COUNTIF(Nominal_Activity!$B$2:$B$5000,$B$5&"-"&F6)+COUNTIF(Trial_Balance!$B$2:$B$4995,$B$5&"-"&F6)>0,"DATA LOADED","NOT LOADED") -> DATA LOADED
A7: Entity ID | B7: PCGH | C7: ID | D7: PC Ghana | F7: Q3 | G7: 46295 | H7: =IF(COUNTIF(Project_Forecast!$B$2:$B$4993,$B$5&"-"&F7)+COUNTIF(Nominal_Activity!$B$2:$B$5000,$B$5&"-"&F7)+COUNTIF(Trial_Balance!$B$2:$B$4995,$B$5&"-"&F7)>0,"DATA LOADED","NOT LOADED") -> NOT LOADED
A8: Entity name | B8: PC Ghana | C8: Text | D8: Confirmed pilot entity | F8: Q4 | G8: 46387 | H8: =IF(COUNTIF(Project_Forecast!$B$2:$B$4993,$B$5&"-"&F8)+COUNTIF(Nominal_Activity!$B$2:$B$5000,$B$5&"-"&F8)+COUNTIF(Trial_Balance!$B$2:$B$4995,$B$5&"-"&F8)>0,"DATA LOADED","NOT LOADED") -> NOT LOADED
A9: Local currency | B9: GHS | C9: Currency | D9: Entity reporting currency
A10: Group currency | B10: GHS | C10: Currency | D10: Consolidation currency
A11: Elapsed months | B11: =MONTH(B4) -> 6 | C11: Months | D11: Formula from reporting date | F11: Quarterly Management Inputs — update the blue cells as each quarter becomes available
A12: Materiality threshold | B12: 50000 | C12: GHS | D12: Default management exception threshold
A13: Materiality percentage | B13: 0.1 | C13: % | D13: Default management exception threshold | F13: Period | G13: Project_Budget_FY | H13: Programme_Budget_FY | I13: Programme_Forecast_FY | J13: Programme_Secured_FY | K13: Programme_Actual_YTD | L13: Other_Budget_FY | M13: Other_Forecast_FY | N13: Other_Actual_YTD | O13: Update_Note | P13: Programme_Invoicing_YTD | Q13: Programme_Income_YTD
A14: Default pipeline probability | B14: 0.7 | C14: % | D14: Applied where source notes say contract not signed | F14: 2026-Q1 | G14: 9794783.6 | H14: 3341189.8 | I14: 3341190 | J14: 3341190 | K14: 725884.66 | L14: 1426884.1 | M14: 1426884.1 | N14: 105344.75 | O14: Pilot data loaded | P14: 0 | Q14: 0
A15: Project income budget | B15: =IFERROR(VLOOKUP($B$30,$F$14:$N$17,2,FALSE()),0) -> 9794783.6 | C15: GHS | D15: Selected-period value from Quarterly Management Inputs | F15: 2026-Q2 | G15: 9794783.6 | H15: 3341189.8 | L15: 1426884.1 | O15: Awaiting Q2 update | P15: 0 | Q15: 0
A16: Programme income budget | B16: =IFERROR(VLOOKUP($B$30,$F$14:$N$17,3,FALSE()),0) -> 3341189.8 | C16: GHS | D16: Selected-period value from Quarterly Management Inputs | F16: 2026-Q3 | G16: 9794783.6 | H16: 3341189.8 | L16: 1426884.1 | O16: Awaiting Q3 update | P16: 0 | Q16: 0
A17: Programme forecast | B17: =IFERROR(VLOOKUP($B$30,$F$14:$N$17,4,FALSE()),0) -> 0 | C17: GHS | D17: Selected-period value from Quarterly Management Inputs | F17: 2026-Q4 | G17: 9794783.6 | H17: 3341189.8 | L17: 1426884.1 | O17: Awaiting Q4 update | P17: 0 | Q17: 0
A18: Programme secured | B18: =IFERROR(VLOOKUP($B$30,$F$14:$N$17,5,FALSE()),0) -> 0 | C18: GHS | D18: Selected-period value from Quarterly Management Inputs
A19: Programme WIP YTD | B19: =IFERROR(VLOOKUP($B$30,$F$14:$N$17,6,FALSE()),0) -> 0 | C19: GHS | D19: Selected-period value from Quarterly Management Inputs
A20: Other income budget | B20: =IFERROR(VLOOKUP($B$30,$F$14:$N$17,7,FALSE()),0) -> 1426884.1 | C20: GHS | D20: Selected-period value from Quarterly Management Inputs
A21: Other income forecast | B21: =IFERROR(VLOOKUP($B$30,$F$14:$N$17,8,FALSE()),0) -> 0 | C21: GHS | D21: Selected-period value from Quarterly Management Inputs
A22: Other income actual YTD | B22: =IFERROR(VLOOKUP($B$30,$F$14:$N$17,9,FALSE()),0) -> 0 | C22: GHS | D22: Selected-period value from Quarterly Management Inputs
A23: Approval status | B23: Draft | C23: Status | D23: Finance approver changes to Approved
A24: Finance approver | B24: Finance Lead | C24: Role | D24: Publication authority
A25: Workbook version | B25: v2.5 | C25: Version | D25: v2.5 2026-08-13: (1) Balance_Sheet — Selected Quarter Opening/Closing block (H:K): Opening = prior-quarter TB closing balance, derived automatically from the reporting quarter in Controls (falls back to the selected snapshot’s TB opening column when the prior-quarter TB is not loaded; Q1 uses the Q1 TB opening balances); Closing = the selected quarter’s own TB closing position. Historical Q1-Q4 columns (B:E) are unchanged and stay fixed per quarter. QMR_Report movement column repointed to the new block; opening balance-sheet and continuity checks added (Checks rows 42-43); row-39 continuity formula repaired to compare asset-line TB openings against prior-quarter closing assets (previously it summed the whole TB, which nets to zero). (2) PA_TB_Recon rebuilt — reconciles Project_Activity (actual project accounting activity) against the Trial_Balance by nominal code, YTD to the comparison quarter: PA total vs TB total, variance, RECONCILED/VARIANCE/INFO status with tolerance input, completeness row for unmapped codes, and a Project × Nominal Code × Period drill-down. Projects Forecast is no longer part of this reconciliation. | v2.4 2026-07-27: (1) Balance_Sheet quarter cols rebuilt as period-driven SUMIFS on the account-code mapping implied by the entered formulas (closing balance, natural TB signs); Master_Mappings extended, movement cols repaired. (2) Next-quarter-opening fallback removed — unloaded quarters show "-". (3) Project_Forecast rebuilt on INDEX/MATCH by Project_ID, capacity MM_Income rows 5-204 → PF rows 2-201, S4/S8/S9 repaired. (4) PA_TB_Recon col D re-sourced to Project_Forecast flow-group columns. (5) QMR_Inputs block 6: project income budgets by portfolio and type, wired to QMR_Report S1/S4 and Project_Output. (6) Programme table: Invoicing + YTD columns, wired to QMR_Report and Controls P/Q. Follow-up 2026-07-27: TB snapshot period corrected 2026-Q1→2026-Q2 (openings = 31-Mar = NA YTD-to-Q1 per code; closings = 30-Jun); TBC placeholder IDs uniquified (TBC-01..08); QMR_Inputs Unallocated rows made self-balancing; PA_TB_Recon statuses made Flow_Group-aware.
A26: Source refresh date | B26: 46203 | C26: Date | D26: Latest source data date
A27: PCGH average FX to GHS | B27: 1 | C27: Rate | D27: GHS reporting entity
A28: PCGH closing FX to GHS | B28: 1 | C28: Rate | D28: GHS reporting entity
A29: Publication scope | B29: Entity QMR | C29: Scope | D29: Choose Entity QMR or Consolidated QMR
A30: Selected period key | B30: =B5&"-"&B6 -> 2026-Q2 | C30: System generated | D30: Used by all selected-period reports
A31: Entity and FX Master | H31: Exchange Rate Control Table (to GHS)
H32: Currency | I32: Rate_to_GHS | J32: Source | K32: As_Of
A33: Entity_ID | B33: Entity_Name | C33: Local_Currency | D33: Average_FX_to_GHS | E33: Closing_FX_to_GHS | F33: Data_Status | H33: GHS | I33: 1 | J33: Reporting currency | K33: 2026-03-31
A34: PCGH | B34: PC Ghana | C34: GHS | D34: 1 | E34: 1 | F34: Pilot populated | H34: USD | I34: 10.7 | J34: Requirements doc §1.3 | K34: 2026-03-31
A35: PFI | B35: Proforest Initiative | C35: TBC | F35: Awaiting source pack | H35: GBP | I35: 14.45 | J35: Requirements doc §1.3 | K35: 2026-03-31
A36: PFCD | B36: Proforest Co-develop | C36: TBC | F36: Awaiting source pack | H36: EUR | I36: 10.1215 | J36: Requirements doc §1.3 | K36: 2026-03-31
A37: PFCM | B37: Proforest Cameroon | C37: TBC | F37: Awaiting source pack
A39: QUARTERLY UPDATE CHECKLIST — refresh in this order:
A40: 1. Controls!B4 — set the reporting period end (drives FY, quarter and every report).
A41: 2. Paste the quarter's source packs: Project_Activity, Nominal_Activity, Trial_Balance (append rows).
A42: 3. MM_Income — maintain the yellow inputs: Status (E), contract value and inclusive fees/expenses (K:N), Forecast_Class/Probability (U:V); add new or pipeline projects as ordinary rows (Status=Pipeline, Probability<1).
...

Sheet QMR_Dashboard
A1: ="Executive QMR Dashboard — "&Controls!$B$8&" — "&Controls!$B$30 -> Executive QMR Dashboard — PC Ghana — 2026-Q2
A2: ="All values GHS '000 unless stated | Live view of the selected quarter | Detail on the domain dashboards" -> All values GHS '000 unless stated | Live view of the selected quarter | Detail on the domain dashboards
A4: INCOME · FY FORECAST | C4: FIXED COSTS · YTD | E4: SURPLUS · FY FORECAST | G4: SECURED vs BUDGET | I4: MONTHS OF COST COVER | K4: DATA QUALITY
A5: =QMR_Report!$C$29/1000 -> 18393.381 | C5: =QMR_Report!$F$47/1000 -> 5801.7136 | E5: =QMR_Report!$C$56/1000 -> 4619.009 | G5: =QMR_Report!$G$29 -> 4.4498661 | I5: =IFERROR(--INDEX(Balance_Sheet!$C$36:$F$36,1,VALUE(MID(Controls!$B$6,2,1))),0) -> 5.7737739 | K5: =Checks!$B$3 -> PASS WITH REVIEW
A6: ="vs budget "&TEXT(QMR_Report!$B$29/1000,"#,##0") -> vs budget 3,341 | C6: ="vs YTD budget "&TEXT(FixedCost_Output!$E$3/1000,"#,##0")&" ("&TEXT(FixedCost_Output!$B$5,"0%")&")" -> vs YTD budget 6,887 (84%) | E6: ="vs budget "&TEXT(QMR_Report!$B$56/1000,"#,##0") -> vs budget -9,006 | G6: ="WIP YTD "&TEXT(QMR_Report!$E$29/1000,"#,##0") -> WIP YTD 8,798 | I6: ="target 3.0 | WC "&TEXT(IFERROR(--INDEX(Balance_Sheet!$C$34:$F$34,1,VALUE(MID(Controls!$B$6,2,1))),0)/1000,"#,##0") -> target 3.0 | WC 5,711 | K6: ="fails "&COUNTIF(Checks!$F$8:$F$41,"FAIL")&" | reviews "&COUNTIF(Checks!$F$8:$F$41,"REVIEW") -> fails 0 | reviews 5
H7: INCOME vs COST BY QUARTER (GHS '000)
A8: QUARTERLY PROFILE — INCOME vs COST (GHS '000)
B9: Q1 | C9: Q2 | D9: Q3 | E9: Q4 | F9: FY
A10: Income (WIP basis) | B10: =Project_Output!B30/1000 -> 4910.7961 | C10: =Project_Output!B31/1000 -> 2548.4044 | D10: =Project_Output!B32/1000 -> 2136.143 | E10: =Project_Output!B33/1000 -> 1831.1564 | F10: =SUM(B10:E10) -> 11426.5
A11: Invoiced | B11: =-SUMIFS(Project_Activity!$P$2:$P$2991,Project_Activity!$U$2:$U$2991,"Invoiced Income",Project_Activity!$H$2:$H$2991,">="&DATE(Controls!$B$5,1,1),Project_Activity!$H$2:$H$2991,"<="&EOMONTH(DATE(Controls!$B$5,3,1),0),Project_Activity!$A$2:$A$2991,Controls!$B$7)/1000 -> 2701.8936 | C11: =-SUMIFS(Project_Activity!$P$2:$P$2991,Project_Activity!$U$2:$U$2991,"Invoiced Income",Project_Activity!$H$2:$H$2991,">="&DATE(Controls!$B$5,4,1),Project_Activity!$H$2:$H$2991,"<="&EOMONTH(DATE(Controls!$B$5,6,1),0),Project_Activity!$A$2:$A$2991,Controls!$B$7)/1000 -> 4369.6242 | D11: =-SUMIFS(Project_Activity!$P$2:$P$2991,Project_Activity!$U$2:$U$2991,"Invoiced Income",Project_Activity!$H$2:$H$2991,">="&DATE(Controls!$B$5,7,1),Project_Activity!$H$2:$H$2991,"<="&EOMONTH(DATE(Controls!$B$5,9,1),0),Project_Activity!$A$2:$A$2991,Controls!$B$7)/1000 -> 0 | E11: =-SUMIFS(Project_Activity!$P$2:$P$2991,Project_Activity!$U$2:$U$2991,"Invoiced Income",Project_Activity!$H$2:$H$2991,">="&DATE(Controls!$B$5,10,1),Project_Activity!$H$2:$H$2991,"<="&EOMONTH(DATE(Controls!$B$5,12,1),0),Project_Activity!$A$2:$A$2991,Controls!$B$7)/1000 -> 0 | F11: =SUM(B11:E11) -> 7071.5179
A12: Fixed costs | B12: =SUMIFS(Nominal_Activity!$M$2:$M$3000,Nominal_Activity!$N$2:$N$3000,"<>Excluded — Project/Other",Nominal_Activity!$G$2:$G$3000,">="&DATE(Controls!$B$5,1,1),Nominal_Activity!$G$2:$G$3000,"<="&EOMONTH(DATE(Controls!$B$5,3,1),0),Nominal_Activity!$A$2:$A$3000,Controls!$B$7)/1000 -> 2779.3613 | C12: =SUMIFS(Nominal_Activity!$M$2:$M$3000,Nominal_Activity!$N$2:$N$3000,"<>Excluded — Project/Other",Nominal_Activity!$G$2:$G$3000,">="&DATE(Controls!$B$5,4,1),Nominal_Activity!$G$2:$G$3000,"<="&EOMONTH(DATE(Controls!$B$5,6,1),0),Nominal_Activity!$A$2:$A$3000,Controls!$B$7)/1000 -> 3022.3522 | D12: =SUMIFS(Nominal_Activity!$M$2:$M$3000,Nominal_Activity!$N$2:$N$3000,"<>Excluded — Project/Other",Nominal_Activity!$G$2:$G$3000,">="&DATE(Controls!$B$5,7,1),Nominal_Activity!$G$2:$G$3000,"<="&EOMONTH(DATE(Controls!$B$5,9,1),0),Nominal_Activity!$A$2:$A$3000,Controls!$B$7)/1000 -> 0 | E12: =SUMIFS(Nominal_Activity!$M$2:$M$3000,Nominal_Activity!$N$2:$N$3000,"<>Excluded — Project/Other",Nominal_Activity!$G$2:$G$3000,">="&DATE(Controls!$B$5,10,1),Nominal_Activity!$G$2:$G$3000,"<="&EOMONTH(DATE(Controls!$B$5,12,1),0),Nominal_Activity!$A$2:$A$3000,Controls!$B$7)/1000 -> 0 | F12: =SUM(B12:E12) -> 5801.7136
A13: Surplus | B13: =B10-B12 -> 2131.4348 | C13: =C10-C12 -> -473.94785 | D13: =D10-D12 -> 2136.143 | E13: =E10-E12 -> 1831.1564 | F13: =SUM(B13:E13) -> 5624.7863
A14: Quarters after the selected one show forecast WIP and zero cost until data is loaded.
A17: STATUS SUMMARY
A18: Domain | B18: Metric | C18: Value | D18: Target | E18: Status
A19: Income | B19: Secured vs annual budget | C19: =QMR_Report!$G$29 -> 4.4498661 | D19: ≥ 90% | E19: =IF(QMR_Report!$G$29>=0.9,"OK",IF(QMR_Report!$G$29>=0.7,"REVIEW","FAIL")) -> OK
A20: Costs | B20: Spend vs YTD budget | C20: =FixedCost_Output!$B$5 -> 0.84239249 | D20: 85–110% | E20: =IF(AND(FixedCost_Output!$B$5>=0.85,FixedCost_Output!$B$5<=1.1),"OK","REVIEW") -> REVIEW | H20: BUDGET vs ACTUAL YTD BY CATEGORY (GHS)
A21: Liquidity | B21: Months of core cover | C21: =IFERROR(--INDEX(Balance_Sheet!$C$36:$F$36,1,VALUE(MID(Controls!$B$6,2,1))),0) -> 5.7737739 | D21: ≥ 3.0 | E21: =IF(IFERROR(--INDEX(Balance_Sheet!$C$36:$F$36,1,VALUE(MID(Controls!$B$6,2,1))),0)>=3,"OK",IF(IFERROR(--INDEX(Balance_Sheet!$C$36:$F$36,1,VALUE(MID(Controls!$B$6,2,1))),0)>=1.5,"REVIEW","FAIL")) -> OK
A22: Working capital | B22: Working capital (GHS 000) | C22: =IFERROR(--INDEX(Balance_Sheet!$C$34:$F$34,1,VALUE(MID(Controls!$B$6,2,1))),0)/1000 -> 5711.2079 | D22: > 0 | E22: =IF(IFERROR(--INDEX(Balance_Sheet!$C$34:$F$34,1,VALUE(MID(Controls!$B$6,2,1))),0)>0,"OK","FAIL") -> OK
A23: Balance sheet | B23: A − L − E | C23: =INDEX(Balance_Sheet!$C$30:$F$30,1,VALUE(MID(Controls!$B$6,2,1))) -> 0 | D23: 0 | E23: =IF(ABS(N(INDEX(Balance_Sheet!$C$30:$F$30,1,VALUE(MID(Controls!$B$6,2,1)))))<=1,"OK","FAIL") -> OK
A24: Data quality | B24: Checks banner | C24: =Checks!$B$3 -> PASS WITH REVIEW | D24: PASS | E24: =IF(Checks!$B$3="PASS","OK",IF(Checks!$B$3="FAIL","FAIL","REVIEW")) -> REVIEW
A27: ENTITY VIEW (GHS '000)
A28: Entity | B28: Income (TOI) | C28: Fixed costs | D28: Surplus YTD | E28: Working capital | F28: Status
A29: =Consolidation!B6 -> PC Ghana | B29: =IF(Consolidation!F6="","-",Consolidation!F6/1000) -> 15545.818 | C29: =IF(Consolidation!G6="","-",Consolidation!G6/1000) -> 5801.7136 | D29: =IF(Consolidation!H6="","-",Consolidation!H6/1000) -> 1657.4869 | E29: =IF(Consolidation!I6="","-",Consolidation!I6/1000) -> 5711.2079 | F29: =Consolidation!J6 -> Populated
A30: =Consolidation!B7 -> Proforest Initiative | B30: =IF(Consolidation!F7="","-",Consolidation!F7/1000) -> - | C30: =IF(Consolidation!G7="","-",Consolidation!G7/1000) -> - | D30: =IF(Consolidation!H7="","-",Consolidation!H7/1000) -> - | E30: =IF(Consolidation!I7="","-",Consolidation!I7/1000) -> - | F30: =Consolidation!J7 -> Awaiting source pack
A31: =Consolidation!B8 -> Proforest Co-develop | B31: =IF(Consolidation!F8="","-",Consolidation!F8/1000) -> - | C31: =IF(Consolidation!G8="","-",Consolidation!G8/1000) -> - | D31: =IF(Consolidation!H8="","-",Consolidation!H8/1000) -> - | E31: =IF(Consolidation!I8="","-",Consolidation!I8/1000) -> - | F31: =Consolidation!J8 -> Awaiting source pack
A32: =Consolidation!B9 -> Proforest Cameroon | B32: =IF(Consolidation!F9="","-",Consolidation!F9/1000) -> - | C32: =IF(Consolidation!G9="","-",Consolidation!G9/1000) -> - | D32: =IF(Consolidation!H9="","-",Consolidation!H9/1000) -> - | E32: =IF(Consolidation!I9="","-",Consolidation!I9/1000) -> - | F32: =Consolidation!J9 -> Awaiting source pack
A35: COMMENTARY — OPEN ITEMS (maintained on Mgmt_Commentary)
A36: 1. | B36: =IFERROR(INDEX(Mgmt_Commentary!$A:$A,_xlfn.AGGREGATE(15,6,ROW(Mgmt_Commentary!$I$5:$I$34)/(Mgmt_Commentary!$I$5:$I$34="Open"),1))&": "&INDEX(Mgmt_Commentary!$B:$B,_xlfn.AGGREGATE(15,6,ROW(Mgmt_Commentary!$I$5:$I$34)/(Mgmt_Commentary!$I$5:$I$34="Open"),1))&" → "&INDEX(Mgmt_Commentary!$F:$F,_xlfn.AGGREGATE(15,6,ROW(Mgmt_Commentary!$I$5:$I$34)/(Mgmt_Commentary!$I$5:$I$34="Open"),1))&" ["&INDEX(Mgmt_Commentary!$G:$G,_xlfn.AGGREGATE(15,6,ROW(Mgmt_Commentary!$I$5:$I$34)/(Mgmt_Commentary!$I$5:$I$34="Open"),1))&"]","—") -> Fixed Costs: YTD spend GHS 2.78m is 664k below phased budget (81% of YTD budget) → Confirm monthly phasing with budget holders; replace even phasing if a profile is approved [Finance]
A37: 2. | B37: =IFERROR(INDEX(Mgmt_Commentary!$A:$A,_xlfn.AGGREGATE(15,6,ROW(Mgmt_Commentary!$I$5:$I$34)/(Mgmt_Commentary!$I$5:$I$34="Open"),2))&": "&INDEX(Mgmt_Commentary!$B:$B,_xlfn.AGGREGATE(15,6,ROW(Mgmt_Commentary!$I$5:$I$34)/(Mgmt_Commentary!$I$5:$I$34="Open"),2))&" → "&INDEX(Mgmt_Commentary!$F:$F,_xlfn.AGGREGATE(15,6,ROW(Mgmt_Commentary!$I$5:$I$34)/(Mgmt_Commentary!$I$5:$I$34="Open"),2))&" ["&INDEX(Mgmt_Commentary!$G:$G,_xlfn.AGGREGATE(15,6,ROW(Mgmt_Commentary!$I$5:$I$34)/(Mgmt_Commentary!$I$5:$I$34="Open"),2))&"]","—") -> Project Income: PCGH767 (Presco scoping) WIP at 147% of net forecast → PM to true-up gross forecast in MM_Income for completed projects [Project Leads]
A38: 3. | B38: =IFERROR(INDEX(Mgmt_Commentary!$A:$A,_xlfn.AGGREGATE(15,6,ROW(Mgmt_Commentary!$I$5:$I$34)/(Mgmt_Commentary!$I$5:$I$34="Open"),3))&": "&INDEX(Mgmt_Commentary!$B:$B,_xlfn.AGGREGATE(15,6,ROW(Mgmt_Commentary!$I$5:$I$34)/(Mgmt_Commentary!$I$5:$I$34="Open"),3))&" → "&INDEX(Mgmt_Commentary!$F:$F,_xlfn.AGGREGATE(15,6,ROW(Mgmt_Commentary!$I$5:$I$34)/(Mgmt_Commentary!$I$5:$I$34="Open"),3))&" ["&INDEX(Mgmt_Commentary!$G:$G,_xlfn.AGGREGATE(15,6,ROW(Mgmt_Commentary!$I$5:$I$34)/(Mgmt_Commentary!$I$5:$I$34="Open"),3))&"]","—") -> Executive: Programme income (GHS 3.34m budget) not yet split by portfolio → Provide portfolio split on QMR_Inputs block 1 [Finance Lead]
A39: 4. | B39: =IFERROR(INDEX(Mgmt_Commentary!$A:$A,_xlfn.AGGREGATE(15,6,ROW(Mgmt_Commentary!$I$5:$I$34)/(Mgmt_Commentary!$I$5:$I$34="Open"),4))&": "&INDEX(Mgmt_Commentary!$B:$B,_xlfn.AGGREGATE(15,6,ROW(Mgmt_Commentary!$I$5:$I$34)/(Mgmt_Commentary!$I$5:$I$34="Open"),4))&" → "&INDEX(Mgmt_Commentary!$F:$F,_xlfn.AGGREGATE(15,6,ROW(Mgmt_Commentary!$I$5:$I$34)/(Mgmt_Commentary!$I$5:$I$34="Open"),4))&" ["&INDEX(Mgmt_Commentary!$G:$G,_xlfn.AGGREGATE(15,6,ROW(Mgmt_Commentary!$I$5:$I$34)/(Mgmt_Commentary!$I$5:$I$34="Open"),4))&"]","—") -> —

Sheet QMR_Report
A1: ="Quarterly Management Report — "&Controls!$B$8&" — "&Controls!$B$30 -> Quarterly Management Report — PC Ghana — 2026-Q2
A2: ="All figures GHS unless stated | Data: staging tabs + master mappings | Inputs live on QMR_Inputs only" -> All figures GHS unless stated | Data: staging tabs + master mappings | Inputs live on QMR_Inputs only
A4: SECTION 1 — INCOME AND EXPENDITURE
A5: Line | B5: Annual Budget | C5: FY Forecast | D5: Secured Net | E5: WIP YTD | F5: Invoiced / Actual YTD | G5: Secured vs Budget | H5: WIP vs Budget | I5: Inv&Act vs Budget
A6: Project Income — External
A7: Responsible Sourcing | C7: =SUMIFS(Project_Forecast!$N$2:$N$393,Project_Forecast!$E$2:$E$393,"Responsible Sourcing",Project_Forecast!$G$2:$G$393,"External",Project_Forecast!$B$2:$B$393,Controls!$B$30,Project_Forecast!$A$2:$A$393,Controls!$B$7) -> 0 | D7: =SUMIFS(Project_Forecast!$N$2:$N$393,Project_Forecast!$E$2:$E$393,"Responsible Sourcing",Project_Forecast!$G$2:$G$393,"External",Project_Forecast!$L$2:$L$393,"Secured",Project_Forecast!$B$2:$B$393,Controls!$B$30,Project_Forecast!$A$2:$A$393,Controls!$B$7) -> 0 | E7: =SUMIFS(Project_Forecast!$AD$2:$AD$393,Project_Forecast!$E$2:$E$393,"Responsible Sourcing",Project_Forecast!$G$2:$G$393,"External",Project_Forecast!$B$2:$B$393,Controls!$B$30,Project_Forecast!$A$2:$A$393,Controls!$B$7) -> 0 | F7: =SUMIFS(Project_Forecast!$O$2:$O$393,Project_Forecast!$E$2:$E$393,"Responsible Sourcing",Project_Forecast!$G$2:$G$393,"External",Project_Forecast!$B$2:$B$393,Controls!$B$30,Project_Forecast!$A$2:$A$393,Controls!$B$7) -> 0
A8: Responsible Production | C8: =SUMIFS(Project_Forecast!$N$2:$N$393,Project_Forecast!$E$2:$E$393,"Responsible Production",Project_Forecast!$G$2:$G$393,"External",Project_Forecast!$B$2:$B$393,Controls!$B$30,Project_Forecast!$A$2:$A$393,Controls!$B$7) -> 9760078 | D8: =SUMIFS(Project_Forecast!$N$2:$N$393,Project_Forecast!$E$2:$E$393,"Responsible Production",Project_Forecast!$G$2:$G$393,"External",Project_Forecast!$L$2:$L$393,"Secured",Project_Forecast!$B$2:$B$393,Controls!$B$30,Project_Forecast!$A$2:$A$393,Controls!$B$7) -> 6643820.7 | E8: =SUMIFS(Project_Forecast!$AD$2:$AD$393,Project_Forecast!$E$2:$E$393,"Responsible Production",Project_Forecast!$G$2:$G$393,"External",Project_Forecast!$B$2:$B$393,Controls!$B$30,Project_Forecast!$A$2:$A$393,Controls!$B$7) -> 4656235.4 | F8: =SUMIFS(Project_Forecast!$O$2:$O$393,Project_Forecast!$E$2:$E$393,"Responsible Production",Project_Forecast!$G$2:$G$393,"External",Project_Forecast!$B$2:$B$393,Controls!$B$30,Project_Forecast!$A$2:$A$393,Controls!$B$7) -> 3852516.1
A9: Responsible Finance | C9: =SUMIFS(Project_Forecast!$N$2:$N$393,Project_Forecast!$E$2:$E$393,"Responsible Finance",Project_Forecast!$G$2:$G$393,"External",Project_Forecast!$B$2:$B$393,Controls!$B$30,Project_Forecast!$A$2:$A$393,Controls!$B$7) -> 913245 | D9: =SUMIFS(Project_Forecast!$N$2:$N$393,Project_Forecast!$E$2:$E$393,"Responsible Finance",Project_Forecast!$G$2:$G$393,"External",Project_Forecast!$L$2:$L$393,"Secured",Project_Forecast!$B$2:$B$393,Controls!$B$30,Project_Forecast!$A$2:$A$393,Controls!$B$7) -> 913245 | E9: =SUMIFS(Project_Forecast!$AD$2:$AD$393,Project_Forecast!$E$2:$E$393,"Responsible Finance",Project_Forecast!$G$2:$G$393,"External",Project_Forecast!$B$2:$B$393,Controls!$B$30,Project_Forecast!$A$2:$A$393,Controls!$B$7) -> 696184.8 | F9: =SUMIFS(Project_Forecast!$O$2:$O$393,Project_Forecast!$E$2:$E$393,"Responsible Finance",Project_Forecast!$G$2:$G$393,"External",Project_Forecast!$B$2:$B$393,Controls!$B$30,Project_Forecast!$A$2:$A$393,Controls!$B$7) -> 801822.68
A10: Collaboration | C10: =SUMIFS(Project_Forecast!$N$2:$N$393,Project_Forecast!$E$2:$E$393,"Collaboration",Project_Forecast!$G$2:$G$393,"External",Project_Forecast!$B$2:$B$393,Controls!$B$30,Project_Forecast!$A$2:$A$393,Controls!$B$7) -> 128400 | D10: =SUMIFS(Project_Forecast!$N$2:$N$393,Project_Forecast!$E$2:$E$393,"Collaboration",Project_Forecast!$G$2:$G$393,"External",Project_Forecast!$L$2:$L$393,"Secured",Project_Forecast!$B$2:$B$393,Controls!$B$30,Project_Forecast!$A$2:$A$393,Controls!$B$7) -> 128400 | E10: =SUMIFS(Project_Forecast!$AD$2:$AD$393,Project_Forecast!$E$2:$E$393,"Collaboration",Project_Forecast!$G$2:$G$393,"External",Project_Forecast!$B$2:$B$393,Controls!$B$30,Project_Forecast!$A$2:$A$393,Controls!$B$7) -> 64200 | F10: =SUMIFS(Project_Forecast!$O$2:$O$393,Project_Forecast!$E$2:$E$393,"Collaboration",Project_Forecast!$G$2:$G$393,"External",Project_Forecast!$B$2:$B$393,Controls!$B$30,Project_Forecast!$A$2:$A$393,Controls!$B$7) -> 0
A11: Production Landscape | C11: =SUMIFS(Project_Forecast!$N$2:$N$393,Project_Forecast!$E$2:$E$393,"Production Landscape",Project_Forecast!$G$2:$G$393,"External",Project_Forecast!$B$2:$B$393,Controls!$B$30,Project_Forecast!$A$2:$A$393,Controls!$B$7) -> 0 | D11: =SUMIFS(Project_Forecast!$N$2:$N$393,Project_Forecast!$E$2:$E$393,"Production Landscape",Project_Forecast!$G$2:$G$393,"External",Project_Forecast!$L$2:$L$393,"Secured",Project_Forecast!$B$2:$B$393,Controls!$B$30,Project_Forecast!$A$2:$A$393,Controls!$B$7) -> 0 | E11: =SUMIFS(Project_Forecast!$AD$2:$AD$393,Project_Forecast!$E$2:$E$393,"Production Landscape",Project_Forecast!$G$2:$G$393,"External",Project_Forecast!$B$2:$B$393,Controls!$B$30,Project_Forecast!$A$2:$A$393,Controls!$B$7) -> 0 | F11: =SUMIFS(Project_Forecast!$O$2:$O$393,Project_Forecast!$E$2:$E$393,"Production Landscape",Project_Forecast!$G$2:$G$393,"External",Project_Forecast!$B$2:$B$393,Controls!$B$30,Project_Forecast!$A$2:$A$393,Controls!$B$7) -> 0
A12: Policy & Regulation | C12: =SUMIFS(Project_Forecast!$N$2:$N$393,Project_Forecast!$E$2:$E$393,"Policy & Regulation",Project_Forecast!$G$2:$G$393,"External",Project_Forecast!$B$2:$B$393,Controls!$B$30,Project_Forecast!$A$2:$A$393,Controls!$B$7) -> 0 | D12: =SUMIFS(Project_Forecast!$N$2:$N$393,Project_Forecast!$E$2:$E$393,"Policy & Regulation",Project_Forecast!$G$2:$G$393,"External",Project_Forecast!$L$2:$L$393,"Secured",Project_Forecast!$B$2:$B$393,Controls!$B$30,Project_Forecast!$A$2:$A$393,Controls!$B$7) -> 0 | E12: =SUMIFS(Project_Forecast!$AD$2:$AD$393,Project_Forecast!$E$2:$E$393,"Policy & Regulation",Project_Forecast!$G$2:$G$393,"External",Project_Forecast!$B$2:$B$393,Controls!$B$30,Project_Forecast!$A$2:$A$393,Controls!$B$7) -> 0 | F12: =SUMIFS(Project_Forecast!$O$2:$O$393,Project_Forecast!$E$2:$E$393,"Policy & Regulation",Project_Forecast!$G$2:$G$393,"External",Project_Forecast!$B$2:$B$393,Controls!$B$30,Project_Forecast!$A$2:$A$393,Controls!$B$7) -> 0
A13: Subtotal — External Project Income | B13: =QMR_Inputs!$B$51 -> 0 | C13: =SUM(C7:C12) -> 10801723 | D13: =SUM(D7:D12) -> 7685465.7 | E13: =SUM(E7:E12) -> 5416620.2 | F13: =SUM(F7:F12) -> 4654338.8
A14: Project Income — Internal (via other Proforest entities)
A15: Responsible Sourcing | C15: =SUMIFS(Project_Forecast!$N$2:$N$393,Project_Forecast!$E$2:$E$393,"Responsible Sourcing",Project_Forecast!$G$2:$G$393,"Internal",Project_Forecast!$B$2:$B$393,Controls!$B$30,Project_Forecast!$A$2:$A$393,Controls!$B$7) -> 4090375 | D15: =SUMIFS(Project_Forecast!$N$2:$N$393,Project_Forecast!$E$2:$E$393,"Responsible Sourcing",Project_Forecast!$G$2:$G$393,"Internal",Project_Forecast!$L$2:$L$393,"Secured",Project_Forecast!$B$2:$B$393,Controls!$B$30,Project_Forecast!$A$2:$A$393,Controls!$B$7) -> 4090375 | E15: =SUMIFS(Project_Forecast!$AD$2:$AD$393,Project_Forecast!$E$2:$E$393,"Responsible Sourcing",Project_Forecast!$G$2:$G$393,"Internal",Project_Forecast!$B$2:$B$393,Controls!$B$30,Project_Forecast!$A$2:$A$393,Controls!$B$7) -> 1847024.7 | F15: =SUMIFS(Project_Forecast!$O$2:$O$393,Project_Forecast!$E$2:$E$393,"Responsible Sourcing",Project_Forecast!$G$2:$G$393,"Internal",Project_Forecast!$B$2:$B$393,Controls!$B$30,Project_Forecast!$A$2:$A$393,Controls!$B$7) -> 2294991.8
A16: Responsible Production | C16: =SUMIFS(Project_Forecast!$N$2:$N$393,Project_Forecast!$E$2:$E$393,"Responsible Production",Project_Forecast!$G$2:$G$393,"Internal",Project_Forecast!$B$2:$B$393,Controls!$B$30,Project_Forecast!$A$2:$A$393,Controls!$B$7) -> 0 | D16: =SUMIFS(Project_Forecast!$N$2:$N$393,Project_Forecast!$E$2:$E$393,"Responsible Production",Project_Forecast!$G$2:$G$393,"Internal",Project_Forecast!$L$2:$L$393,"Secured",Project_Forecast!$B$2:$B$393,Controls!$B$30,Project_Forecast!$A$2:$A$393,Controls!$B$7) -> 0 | E16: =SUMIFS(Project_Forecast!$AD$2:$AD$393,Project_Forecast!$E$2:$E$393,"Responsible Production",Project_Forecast!$G$2:$G$393,"Internal",Project_Forecast!$B$2:$B$393,Controls!$B$30,Project_Forecast!$A$2:$A$393,Controls!$B$7) -> 0 | F16: =SUMIFS(Project_Forecast!$O$2:$O$393,Project_Forecast!$E$2:$E$393,"Responsible Production",Project_Forecast!$G$2:$G$393,"Internal",Project_Forecast!$B$2:$B$393,Controls!$B$30,Project_Forecast!$A$2:$A$393,Controls!$B$7) -> 0
A17: Responsible Finance | C17: =SUMIFS(Project_Forecast!$N$2:$N$393,Project_Forecast!$E$2:$E$393,"Responsible Finance",Project_Forecast!$G$2:$G$393,"Internal",Project_Forecast!$B$2:$B$393,Controls!$B$30,Project_Forecast!$A$2:$A$393,Controls!$B$7) -> 653719.44 | D17: =SUMIFS(Project_Forecast!$N$2:$N$393,Project_Forecast!$E$2:$E$393,"Responsible Finance",Project_Forecast!$G$2:$G$393,"Internal",Project_Forecast!$L$2:$L$393,"Secured",Project_Forecast!$B$2:$B$393,Controls!$B$30,Project_Forecast!$A$2:$A$393,Controls!$B$7) -> 244444.44 | E17: =SUMIFS(Project_Forecast!$AD$2:$AD$393,Project_Forecast!$E$2:$E$393,"Responsible Finance",Project_Forecast!$G$2:$G$393,"Internal",Project_Forecast!$B$2:$B$393,Controls!$B$30,Project_Forecast!$A$2:$A$393,Controls!$B$7) -> 195555.55 | F17: =SUMIFS(Project_Forecast!$O$2:$O$393,Project_Forecast!$E$2:$E$393,"Responsible Finance",Project_Forecast!$G$2:$G$393,"Internal",Project_Forecast!$B$2:$B$393,Controls!$B$30,Project_Forecast!$A$2:$A$393,Controls!$B$7) -> 122187.25
A18: Collaboration | C18: =SUMIFS(Project_Forecast!$N$2:$N$393,Project_Forecast!$E$2:$E$393,"Collaboration",Project_Forecast!$G$2:$G$393,"Internal",Project_Forecast!$B$2:$B$393,Controls!$B$30,Project_Forecast!$A$2:$A$393,Controls!$B$7) -> 0 | D18: =SUMIFS(Project_Forecast!$N$2:$N$393,Project_Forecast!$E$2:$E$393,"Collaboration",Project_Forecast!$G$2:$G$393,"Internal",Project_Forecast!$L$2:$L$393,"Secured",Project_Forecast!$B$2:$B$393,Controls!$B$30,Project_Forecast!$A$2:$A$393,Controls!$B$7) -> 0 | E18: =SUMIFS(Project_Forecast!$AD$2:$AD$393,Project_Forecast!$E$2:$E$393,"Collaboration",Project_Forecast!$G$2:$G$393,"Internal",Project_Forecast!$B$2:$B$393,Controls!$B$30,Project_Forecast!$A$2:$A$393,Controls!$B$7) -> 0 | F18: =SUMIFS(Project_Forecast!$O$2:$O$393,Project_Forecast!$E$2:$E$393,"Collaboration",Project_Forecast!$G$2:$G$393,"Internal",Project_Forecast!$B$2:$B$393,Controls!$B$30,Project_Forecast!$A$2:$A$393,Controls!$B$7) -> 0
A19: Production Landscape | C19: =SUMIFS(Project_Forecast!$N$2:$N$393,Project_Forecast!$E$2:$E$393,"Production Landscape",Project_Forecast!$G$2:$G$393,"Internal",Project_Forecast!$B$2:$B$393,Controls!$B$30,Project_Forecast!$A$2:$A$393,Controls!$B$7) -> 0 | D19: =SUMIFS(Project_Forecast!$N$2:$N$393,Project_Forecast!$E$2:$E$393,"Production Landscape",Project_Forecast!$G$2:$G$393,"Internal",Project_Forecast!$L$2:$L$393,"Secured",Project_Forecast!$B$2:$B$393,Controls!$B$30,Project_Forecast!$A$2:$A$393,Controls!$B$7) -> 0 | E19: =SUMIFS(Project_Forecast!$AD$2:$AD$393,Project_Forecast!$E$2:$E$393,"Production Landscape",Project_Forecast!$G$2:$G$393,"Internal",Project_Forecast!$B$2:$B$393,Controls!$B$30,Project_Forecast!$A$2:$A$393,Controls!$B$7) -> 0 | F19: =SUMIFS(Project_Forecast!$O$2:$O$393,Project_Forecast!$E$2:$E$393,"Production Landscape",Project_Forecast!$G$2:$G$393,"Internal",Project_Forecast!$B$2:$B$393,Controls!$B$30,Project_Forecast!$A$2:$A$393,Controls!$B$7) -> 0
A20: Policy & Regulation | C20: =SUMIFS(Project_Forecast!$N$2:$N$393,Project_Forecast!$E$2:$E$393,"Policy & Regulation",Project_Forecast!$G$2:$G$393,"Internal",Project_Forecast!$B$2:$B$393,Controls!$B$30,Project_Forecast!$A$2:$A$393,Controls!$B$7) -> 0 | D20: =SUMIFS(Project_Forecast!$N$2:$N$393,Project_Forecast!$E$2:$E$393,"Policy & Regulation",Project_Forecast!$G$2:$G$393,"Internal",Project_Forecast!$L$2:$L$393,"Secured",Project_Forecast!$B$2:$B$393,Controls!$B$30,Project_Forecast!$A$2:$A$393,Controls!$B$7) -> 0 | E20: =SUMIFS(Project_Forecast!$AD$2:$AD$393,Project_Forecast!$E$2:$E$393,"Policy & Regulation",Project_Forecast!$G$2:$G$393,"Internal",Project_Forecast!$B$2:$B$393,Controls!$B$30,Project_Forecast!$A$2:$A$393,Controls!$B$7) -> 0 | F20: =SUMIFS(Project_Forecast!$O$2:$O$393,Project_Forecast!$E$2:$E$393,"Policy & Regulation",Project_Forecast!$G$2:$G$393,"Internal",Project_Forecast!$B$2:$B$393,Controls!$B$30,Project_Forecast!$A$2:$A$393,Controls!$B$7) -> 0
A21: Subtotal — Internal Project Income | B21: =QMR_Inputs!$B$52 -> 0 | C21: =SUM(C15:C20) -> 4744094.5 | D21: =SUM(D15:D20) -> 4334819.5 | E21: =SUM(E15:E20) -> 2042580.3 | F21: =SUM(F15:F20) -> 2417179.1
A22: Other / unmapped projects | C22: =SUMIFS(Project_Forecast!$N$2:$N$393,Project_Forecast!$B$2:$B$393,Controls!$B$30,Project_Forecast!$A$2:$A$393,Controls!$B$7)-C13-C21 -> 0 | D22: =SUMIFS(Project_Forecast!$N$2:$N$393,Project_Forecast!$L$2:$L$393,"Secured",Project_Forecast!$B$2:$B$393,Controls!$B$30,Project_Forecast!$A$2:$A$393,Controls!$B$7)-D13-D21 -> 0 | E22: =SUMIFS(Project_Forecast!$AD$2:$AD$393,Project_Forecast!$B$2:$B$393,Controls!$B$30,Project_Forecast!$A$2:$A$393,Controls!$B$7)-E13-E21 -> 0 | F22: =SUMIFS(Project_Forecast!$O$2:$O$393,Project_Forecast!$B$2:$B$393,Controls!$B$30,Project_Forecast!$A$2:$A$393,Controls!$B$7)-F13-F21 -> 0
A23: Total Project Income | B23: =B13+B21 -> 0 | C23: =C13+C21+C22 -> 15545818 | D23: =D13+D21+D22 -> 12020285 | E23: =E13+E21+E22 -> 7459200.5 | F23: =F13+F21+F22 -> 7071517.9 | G23: =IFERROR(D23/B23,0) -> 0 | H23: =IFERROR(E23/B23,0) -> 0 | I23: =IFERROR(F23/B23,0) -> 0
A24: Programme Income (by Portfolio)
A25: Production Landscape | B25: =QMR_Inputs!B6 -> 2347805 | C25: =QMR_Inputs!C6 -> 2347805 | D25: =QMR_Inputs!D6 -> 2347805 | E25: =QMR_Inputs!E6 -> 945514 | F25: =QMR_Inputs!G6 -> 0
A26: Collaboration | B26: =QMR_Inputs!B7 -> 993385 | C26: =QMR_Inputs!C7 -> 499758 | D26: =QMR_Inputs!D7 -> 499758 | E26: =QMR_Inputs!E7 -> 393304 | F26: =QMR_Inputs!G7 -> 0
A27: Policy & Regulation | B27: =QMR_Inputs!B8 -> 0 | C27: =QMR_Inputs!C8 -> 0 | D27: =QMR_Inputs!D8 -> 0 | E27: =QMR_Inputs!E8 -> 0 | F27: =QMR_Inputs!G8 -> 0
A28: Total Programme Income | B28: =SUM(B25:B27) -> 3341190 | C28: =SUM(C25:C27) -> 2847563 | D28: =SUM(D25:D27) -> 2847563 | E28: =SUM(E25:E27) -> 1338818 | F28: =SUM(F25:F27) -> 0 | G28: =IFERROR(D28/B28,0) -> 0.85226012 | H28: =IFERROR(E28/B28,0) -> 0.40070095 | I28: =IFERROR(F28/B28,0) -> 0
A29: TOTAL OPERATING INCOME | B29: =B23+B28 -> 3341190 | C29: =C23+C28 -> 18393381 | D29: =D23+D28 -> 14867848 | E29: =E23+E28 -> 8798018.5 | F29: =F23+F28 -> 7071517.9 | G29: =IFERROR(D29/B29,0) -> 4.4498661 | H29: =IFERROR(E29/B29,0) -> 2.6331991 | I29: =IFERROR(F29/B29,0) -> 2.1164669
A31: Expenditure
A32: Direct Technical Costs | B32: =SUMIFS(MM_FixedCost!$F$5:$F$78,MM_FixedCost!$C$5:$C$78,"Direct technical costs") -> 7230077.7 | C32: =B32 -> 7230077.7 | D32: =F32 -> 3229268.5 | E32: =F32 -> 3229268.5 | F32: =SUMIFS(Nominal_Activity!$M$2:$M$3000,Nominal_Activity!$N$2:$N$3000,"Direct technical costs",Nominal_Activity!$G$2:$G$3000,">="&DATE(Controls!$B$5,1,1),Nominal_Activity!$G$2:$G$3000,"<="&Controls!$B$4,Nominal_Activity!$A$2:$A$3000,Controls!$B$7) -> 3229268.5
A33: Contribution from Group re Global Roles (Technical) | B33: =QMR_Inputs!B19 -> 0 | C33: =B33 -> 0 | D33: =F33 -> 0 | E33: =F33 -> 0 | F33: =QMR_Inputs!C19 -> 0
A34: Direct FinOps Costs | B34: =SUMIFS(MM_FixedCost!$F$5:$F$78,MM_FixedCost!$C$5:$C$78,"Direct support costs") -> 2322680 | C34: =B34 -> 2322680 | D34: =F34 -> 1287623.6 | E34: =F34 -> 1287623.6 | F34: =SUMIFS(Nominal_Activity!$M$2:$M$3000,Nominal_Activity!$N$2:$N$3000,"Direct support costs",Nominal_Activity!$G$2:$G$3000,">="&DATE(Controls!$B$5,1,1),Nominal_Activity!$G$2:$G$3000,"<="&Controls!$B$4,Nominal_Activity!$A$2:$A$3000,Controls!$B$7) -> 1287623.6
A35: Contribution from Group re Global Roles (FinOps) | B35: =QMR_Inputs!B20 -> 0 | C35: =B35 -> 0 | D35: =F35 -> 0 | E35: =F35 -> 0 | F35: =QMR_Inputs!C20 -> 0
A36: Indirect Costs from Group Payroll (Global Roles) | B36: =QMR_Inputs!B21 -> 0 | C36: =B36 -> 0 | D36: =F36 -> 0 | E36: =F36 -> 0 | F36: =QMR_Inputs!C21 -> 0
A37: Total Personnel Costs | B37: =SUM(B32:B36) -> 9552757.7 | C37: =SUM(C32:C36) -> 9552757.7 | D37: =SUM(D32:D36) -> 4516892.2 | E37: =SUM(E32:E36) -> 4516892.2 | F37: =SUM(F32:F36) -> 4516892.2
A38: Recruitment and Benefits | B38: =SUMIFS(MM_FixedCost!$F$5:$F$78,MM_FixedCost!$C$5:$C$78,"Recruitment, Benefits") -> 321500 | C38: =B38 -> 321500 | D38: =F38 -> 89499.71 | E38: =F38 -> 89499.71 | F38: =SUMIFS(Nominal_Activity!$M$2:$M$3000,Nominal_Activity!$N$2:$N$3000,"Recruitment, Benefits",Nominal_Activity!$G$2:$G$3000,">="&DATE(Controls!$B$5,1,1),Nominal_Activity!$G$2:$G$3000,"<="&Controls!$B$4,Nominal_Activity!$A$2:$A$3000,Controls!$B$7) -> 89499.71
A39: Professional Development and Training | B39: =SUMIFS(MM_FixedCost!$F$5:$F$78,MM_FixedCost!$C$5:$C$78,"Professional development and Training") -> 1217997 | C39: =B39 -> 1217997 | D39: =F39 -> 201138.6 | E39: =F39 -> 201138.6 | F39: =SUMIFS(Nominal_Activity!$M$2:$M$3000,Nominal_Activity!$N$2:$N$3000,"Professional development and Training",Nominal_Activity!$G$2:$G$3000,">="&DATE(Controls!$B$5,1,1),Nominal_Activity!$G$2:$G$3000,"<="&Controls!$B$4,Nominal_Activity!$A$2:$A$3000,Controls!$B$7) -> 201138.6
A40: Business Development and Comms | B40: =SUMIFS(MM_FixedCost!$F$5:$F$78,MM_FixedCost!$C$5:$C$78,"Business development and Comms") -> 247369.45 | C40: =B40 -> 247369.45 | D40: =F40 -> 99295.87 | E40: =F40 -> 99295.87 | F40: =SUMIFS(Nominal_Activity!$M$2:$M$3000,Nominal_Activity!$N$2:$N$3000,"Business development and Comms",Nominal_Activity!$G$2:$G$3000,">="&DATE(Controls!$B$5,1,1),Nominal_Activity!$G$2:$G$3000,"<="&Controls!$B$4,Nominal_Activity!$A$2:$A$3000,Controls!$B$7) -> 99295.87
A41: Internal Events and Meetings | B41: =SUMIFS(MM_FixedCost!$F$5:$F$78,MM_FixedCost!$C$5:$C$78,"Internal events and meetings") -> 439040 | C41: =B41 -> 439040 | D41: =F41 -> 33622.84 | E41: =F41 -> 33622.84 | F41: =SUMIFS(Nominal_Activity!$M$2:$M$3000,Nominal_Activity!$N$2:$N$3000,"Internal events and meetings",Nominal_Activity!$G$2:$G$3000,">="&DATE(Controls!$B$5,1,1),Nominal_Activity!$G$2:$G$3000,"<="&Controls!$B$4,Nominal_Activity!$A$2:$A$3000,Controls!$B$7) -> 33622.84
A42: Professional Services and Governance | B42: =SUMIFS(MM_FixedCost!$F$5:$F$78,MM_FixedCost!$C$5:$C$78,"Professional services and governance") -> 1028561.7 | C42: =B42 -> 1028561.7 | D42: =F42 -> 684241.87 | E42: =F42 -> 684241.87 | F42: =SUMIFS(Nominal_Activity!$M$2:$M$3000,Nominal_Activity!$N$2:$N$3000,"Professional services and governance",Nominal_Activity!$G$2:$G$3000,">="&DATE(Controls!$B$5,1,1),Nominal_Activity!$G$2:$G$3000,"<="&Controls!$B$4,Nominal_Activity!$A$2:$A$3000,Controls!$B$7) -> 684241.87
...

Sheet Slide_Pack
A1: ="QMR Slide Pack — "&Controls!$B$8&" — "&Controls!$B$30&" (GHS 000)" -> QMR Slide Pack — PC Ghana — 2026-Q2 (GHS 000)
A2: All figures link to QMR_Report / Balance_Sheet. Copy tables and charts into the slide template.
A4: Slide 1 — Overview (GHS 000)
A5: Line | B5: Budget (FY) | C5: Forecast (FY) | D5: Secured (YTD) | E5: WIP (YTD) | F5: Secured vs higher of Budget/Forecast | G5: WIP vs higher of Budget/Forecast
A6: Total Project Income | B6: =QMR_Report!B23/1000 -> 0 | C6: =QMR_Report!C23/1000 -> 15545.818 | D6: =QMR_Report!D23/1000 -> 12020.285 | E6: =QMR_Report!E23/1000 -> 7459.2005 | F6: =IFERROR(D6/MAX(B6,C6),0) -> 0.77321667 | G6: =IFERROR(E6/MAX(B6,C6),0) -> 0.47982041
A7: Total Programme Income | B7: =QMR_Report!B28/1000 -> 3341.19 | C7: =QMR_Report!C28/1000 -> 2847.563 | D7: =QMR_Report!D28/1000 -> 2847.563 | E7: =QMR_Report!E28/1000 -> 1338.818 | F7: =IFERROR(D7/MAX(B7,C7),0) -> 0.85226012 | G7: =IFERROR(E7/MAX(B7,C7),0) -> 0.40070095
A8: TOTAL INCOME | B8: =QMR_Report!B29/1000 -> 3341.19 | C8: =QMR_Report!C29/1000 -> 18393.381 | D8: =QMR_Report!D29/1000 -> 14867.848 | E8: =QMR_Report!E29/1000 -> 8798.0185 | F8: =IFERROR(D8/MAX(B8,C8),0) -> 0.80832603 | G8: =IFERROR(E8/MAX(B8,C8),0) -> 0.47832526
A9: Fixed Costs | B9: =QMR_Report!B47/1000 -> 13774.372 | C9: =QMR_Report!C47/1000 -> 13774.372 | D9: =QMR_Report!F47/1000 -> 5801.7136 | E9: =QMR_Report!F47/1000 -> 5801.7136 | F9: =IFERROR(D9/MAX(B9,C9),0) -> 0.42119625 | G9: =IFERROR(E9/MAX(B9,C9),0) -> 0.42119625
A10: Other Income | B10: =QMR_Report!B53/1000 -> 1426.8842 | C10: =QMR_Report!C53/1000 -> 0 | D10: =QMR_Report!F53/1000 -> 186.79618 | E10: =QMR_Report!F53/1000 -> 186.79618 | F10: =IFERROR(D10/MAX(B10,C10),0) -> 0.13091195 | G10: =IFERROR(E10/MAX(B10,C10),0) -> 0.13091195
A11: TOTAL FIXED COSTS (after other income) | B11: =B9-B10 -> 12347.487 | C11: =C9-C10 -> 13774.372 | D11: =D9-D10 -> 5614.9174 | E11: =E9-E10 -> 5614.9174 | F11: =IFERROR(D11/MAX(B11,C11),0) -> 0.40763511 | G11: =IFERROR(E11/MAX(B11,C11),0) -> 0.40763511
A12: (Deficit)/Surplus (before depreciation and tax) | B12: =B8-B11 -> -9006.2974 | C12: =C8-C11 -> 4619.009 | D12: =D8-D11 -> 9252.9308 | E12: =E8-E11 -> 3183.1011 | F12: =IFERROR(D12/MAX(B12,C12),0) -> 2.0032286 | G12: =IFERROR(E12/MAX(B12,C12),0) -> 0.68913075
A13: (Deficit)/Surplus (after depreciation and tax) | B13: =B12-(QMR_Report!B57+QMR_Report!B58)/1000 -> -9006.2974 | C13: =C12-(QMR_Report!C57+QMR_Report!C58)/1000 -> 4619.009 | D13: =D12-(QMR_Report!F57+QMR_Report!F58)/1000 -> 9252.9308 | E13: =E12-(QMR_Report!F57+QMR_Report!F58)/1000 -> 3183.1011 | F13: =IFERROR(D13/MAX(B13,C13),0) -> 2.0032286 | G13: =IFERROR(E13/MAX(B13,C13),0) -> 0.68913075
A14: (Deficit)/Surplus % | B14: =IFERROR(B13/B8,0) -> -2.6955358 | C14: =IFERROR(C13/C8,0) -> 0.25112344 | D14: =IFERROR(D13/D8,0) -> 0.62234499 | E14: =IFERROR(E13/E8,0) -> 0.3617975
A15: Notes: "Forecast (FY)" for fixed-cost lines = Annual Budget (no separate fixed-cost reforecast is maintained — requirement 2.4 removed Forecast FY). Quarters not yet loaded show "-".
A17: Slide 2 — Fixed Costs (GHS 000) — chart & pie version
A18: Cost category | B18: Budget (FY) | C18: Forecast (FY) | D18: Actual (YTD) | E18: Actual vs Budget | F18: Actual vs Forecast | G18: % of total Budget | H18: % of total Actuals
A19: Direct Technical Costs | B19: =SUMIFS(FixedCost_Output!$C$12:$C$22,FixedCost_Output!$B$12:$B$22,$A19)/1000 -> 7230.0777 | C19: =B19 -> 7230.0777 | D19: =SUMIFS(FixedCost_Output!$E$12:$E$22,FixedCost_Output!$B$12:$B$22,$A19)/1000 -> 3229.2685 | E19: =IFERROR(D19/B19,0) -> 0.44664369 | F19: =IFERROR(D19/C19,0) -> 0.44664369 | G19: =IFERROR(B19/B$22,0) -> 0.52489347 | H19: =IFERROR(D19/D$22,0) -> 0.55660599
A20: Direct FinOps Costs | B20: =SUMIFS(FixedCost_Output!$C$12:$C$22,FixedCost_Output!$B$12:$B$22,$A20)/1000 -> 2322.68 | C20: =B20 -> 2322.68 | D20: =SUMIFS(FixedCost_Output!$E$12:$E$22,FixedCost_Output!$B$12:$B$22,$A20)/1000 -> 1287.6236 | E20: =IFERROR(D20/B20,0) -> 0.5543698 | F20: =IFERROR(D20/C20,0) -> 0.5543698 | G20: =IFERROR(B20/B$22,0) -> 0.1686233 | H20: =IFERROR(D20/D$22,0) -> 0.22193851
A21: Other Fixed Costs | B21: =SUMIFS(FixedCost_Output!$C$12:$C$22,FixedCost_Output!$B$12:$B$22,$A21)/1000 -> 4221.6138 | C21: =B21 -> 4221.6138 | D21: =SUMIFS(FixedCost_Output!$E$12:$E$22,FixedCost_Output!$B$12:$B$22,$A21)/1000 -> 1284.8214 | E21: =IFERROR(D21/B21,0) -> 0.30434365 | F21: =IFERROR(D21/C21,0) -> 0.30434365 | G21: =IFERROR(B21/B$22,0) -> 0.30648323 | H21: =IFERROR(D21/D$22,0) -> 0.2214555
A22: TOTAL | B22: =SUM(B19:B21) -> 13774.372 | C22: =SUM(C19:C21) -> 13774.372 | D22: =SUM(D19:D21) -> 5801.7136 | E22: =IFERROR(D22/B22,0) -> 0.42119625 | F22: =IFERROR(D22/C22,0) -> 0.42119625 | G22: =IFERROR(B22/B22,0) -> 1 | H22: =IFERROR(D22/D22,0) -> 1
A23: Note: Actual (YTD) reflects nominal activity through the selected quarter end only.
A25: Slide 3 — Working Capital
A26: Metric | B26: Value | C26: Note
A27: Current Ratio | B27: =INDEX(Balance_Sheet!$C$33:$F$33,1,VALUE(MID(Controls!$B$6,2,1))) -> 2.761659 | C27: 1 or more is considered good — if below 1, explain
A28: Total Current Assets ('000) | B28: =IFERROR(INDEX(Balance_Sheet!$B$13:$E$13,1,VALUE(MID(Controls!$B$6,2,1)))/1000,"-") -> 8953.1565
A29: Total Current Liabilities ('000) | B29: =IFERROR(INDEX(Balance_Sheet!$B$18:$E$18,1,VALUE(MID(Controls!$B$6,2,1)))/1000,"-") -> -3241.9486
A30: Working Capital ('000) | B30: =IFERROR(INDEX(Balance_Sheet!$C$34:$F$34,1,VALUE(MID(Controls!$B$6,2,1)))/1000,"-") -> 5711.2079 | C30: Total Current Assets less Total Current Liabilities
A31: Core Costs per Month ('000) | B31: =IFERROR(INDEX(Balance_Sheet!$C$35:$F$35,1,VALUE(MID(Controls!$B$6,2,1)))/1000,"-") -> 989.16376
A32: No. of Months' Cover | B32: =INDEX(Balance_Sheet!$C$36:$F$36,1,VALUE(MID(Controls!$B$6,2,1))) -> 5.7737739 | C32: Initial target is 3 months
A33: Core Fixed Costs ('000) | B33: =SUMIFS(MM_FixedCost!$F$5:$F$78,MM_FixedCost!$E$5:$E$78,"Core")/1000 -> 11869.965
A34: Discretionary Fixed Costs ('000) | B34: =SUMIFS(MM_FixedCost!$F$5:$F$78,MM_FixedCost!$E$5:$E$78,"Discretionary")/1000 -> 1904.4065
A35: Total Fixed Costs ('000) | B35: =FixedCost_Output!$B$3/1000 -> 13774.372
A38: Data Set 5 — Balance Sheet extract feeding Working Capital (GHS 000)
A39: Balance sheet line | B39: GHS '000
A40: Total Fixed Assets | B40: =IFERROR(INDEX(Balance_Sheet!$B$8:$E$8,1,VALUE(MID(Controls!$B$6,2,1)))/1000,"-") -> 2304.2648
A41: Total Current Assets | B41: =IFERROR(INDEX(Balance_Sheet!$B$13:$E$13,1,VALUE(MID(Controls!$B$6,2,1)))/1000,"-") -> 8953.1565
A42: Total Current Liabilities | B42: =IFERROR(INDEX(Balance_Sheet!$B$18:$E$18,1,VALUE(MID(Controls!$B$6,2,1)))/1000,"-") -> -3241.9486
A43: Long Term Liabilities | B43: =IFERROR(INDEX(Balance_Sheet!$B$21:$E$21,1,VALUE(MID(Controls!$B$6,2,1)))/1000,"-") -> -0.00033
A44: Total Assets Less Liabilities | B44: =IFERROR(INDEX(Balance_Sheet!$B$24:$E$24,1,VALUE(MID(Controls!$B$6,2,1)))/1000,"-") -> 8015.4724
A45: Total Capital and Reserves | B45: =IFERROR(INDEX(Balance_Sheet!$B$25:$E$25,1,VALUE(MID(Controls!$B$6,2,1)))/1000,"-") -> -8015.4724
...

Sheet Project_Output
A1: ="Project Income and Forecast — "&Controls!$B$8 -> Project Income and Forecast — PC Ghana
A2: ="Selected period: "&Controls!$B$30&" | Net income forecast, secured position, WIP and invoicing" -> Selected period: 2026-Q2 | Net income forecast, secured position, WIP and invoicing
A3: Gross Forecast (GHS) | B3: =SUM(MM_Income!$P$5:$P$204) -> 16502775 | D3: Net Forecast (GHS) | E3: =SUMIFS(Project_Forecast!$N$2:$N$393,Project_Forecast!$B$2:$B$393,Controls!$B$30,Project_Forecast!$A$2:$A$393,Controls!$B$7) -> 15545818 | G3: Secured Net Forecast (GHS) | H3: =SUMIFS(Project_Forecast!$N$2:$N$393,Project_Forecast!$L$2:$L$393,"Secured",Project_Forecast!$B$2:$B$393,Controls!$B$30,Project_Forecast!$A$2:$A$393,Controls!$B$7) -> 12020285 | J3: WIP YTD (GHS) | K3: =SUMIFS(Project_Forecast!$AD$2:$AD$393,Project_Forecast!$B$2:$B$393,Controls!$B$30,Project_Forecast!$A$2:$A$393,Controls!$B$7) -> 7459200.5
A5: Net Invoiced YTD (GHS) | B5: =SUMIFS(Project_Forecast!$S$2:$S$393,Project_Forecast!$B$2:$B$393,Controls!$B$30,Project_Forecast!$A$2:$A$393,Controls!$B$7) -> 6495719.3 | D5: Forecast WIP — remaining qtrs | E5: =SUMIFS(Project_Forecast!$AE$2:$AE$393,Project_Forecast!$B$2:$B$393,Controls!$B$30,Project_Forecast!$A$2:$A$393,Controls!$B$7) -> 3967299.4 | G5: Management Exceptions | H5: =COUNTIFS(Project_Forecast!$AI$2:$AI$393,"REVIEW",Project_Forecast!$B$2:$B$393,Controls!$B$30,Project_Forecast!$A$2:$A$393,Controls!$B$7) -> 16 | J5: Secured vs Budget | K5: =IFERROR(H3/Controls!$B$15,0) -> 1.227213
A6: FY Gross (incl pipeline) | B6: =SUM(MM_Income!$P$5:$P$204) -> 16502775 | D6: FY Net (incl pipeline) | E6: =SUM(MM_Income!$T$5:$T$204) -> 15545818 | G6: FY Secured Net | H6: =SUMIFS(MM_Income!$T$5:$T$204,MM_Income!$U$5:$U$204,"Secured") -> 12020285 | J6: FY Pipeline Net | K6: =SUMIFS(MM_Income!$T$5:$T$204,MM_Income!$U$5:$U$204,"Pipeline") -> 3525532.3
A7: FY Weighted Net (× Prob) | B7: =SUM(MM_Income!$W$5:$W$204) -> 15146686 | D7: Full-year view from MM_Income (incl pipeline). Row 3 shows the selected reporting period.
A8: Income by Project Type and Portfolio — selected period
A9: Project_Type | B9: Portfolio | C9: Gross_Forecast | D9: Net_Forecast | E9: Secured_Net | F9: WIP_Current_Qtr | G9: WIP_Cum_YTD | H9: WIP_Fcst_Remaining | I9: Net_Invoiced_YTD | J9: WIP_Q1 | K9: WIP_Q2 | L9: WIP_Q3 | M9: WIP_Q4 | N9: Portfolio | O9: Net_Forecast | P9: Annual_Budget | Q9: Fcst_vs_Budget
A10: External | B10: Responsible Sourcing | C10: =SUMIFS(MM_Income!$P$5:$P$204,MM_Income!$C$5:$C$204,$B10,MM_Income!$G$5:$G$204,$A10) -> 0 | D10: =SUMIFS(Project_Forecast!$N$2:$N$393,Project_Forecast!$E$2:$E$393,$B10,Project_Forecast!$G$2:$G$393,$A10,Project_Forecast!$B$2:$B$393,Controls!$B$30,Project_Forecast!$A$2:$A$393,Controls!$B$7) -> 0 | E10: =SUMIFS(Project_Forecast!$N$2:$N$393,Project_Forecast!$E$2:$E$393,$B10,Project_Forecast!$G$2:$G$393,$A10,Project_Forecast!$L$2:$L$393,"Secured",Project_Forecast!$B$2:$B$393,Controls!$B$30,Project_Forecast!$A$2:$A$393,Controls!$B$7) -> 0 | F10: =CHOOSE(VALUE(MID(Controls!$B$6,2,1)),SUMIFS(Project_Forecast!$W$2:$W$393,Project_Forecast!$E$2:$E$393,$B10,Project_Forecast!$G$2:$G$393,$A10,Project_Forecast!$B$2:$B$393,Controls!$B$30,Project_Forecast!$A$2:$A$393,Controls!$B$7),SUMIFS(Project_Forecast!$Y$2:$Y$393,Project_Forecast!$E$2:$E$393,$B10,Project_Forecast!$G$2:$G$393,$A10,Project_Forecast!$B$2:$B$393,Controls!$B$30,Project_Forecast!$A$2:$A$393,Controls!$B$7),SUMIFS(Project_Forecast!$AA$2:$AA$393,Project_Forecast!$E$2:$E$393,$B10,Project_Forecast!$G$2:$G$393,$A10,Project_Forecast!$B$2:$B$393,Controls!$B$30,Project_Forecast!$A$2:$A$393,Controls!$B$7),SUMIFS(Project_Forecast!$AC$2:$AC$393,Project_Forecast!$E$2:$E$393,$B10,Project_Forecast!$G$2:$G$393,$A10,Project_Forecast!$B$2:$B$393,Controls!$B$30,Project_Forecast!$A$2:$A$393,Controls!$B$7)) -> 0 | G10: =SUMIFS(Project_Forecast!$AD$2:$AD$393,Project_Forecast!$E$2:$E$393,$B10,Project_Forecast!$G$2:$G$393,$A10,Project_Forecast!$B$2:$B$393,Controls!$B$30,Project_Forecast!$A$2:$A$393,Controls!$B$7) -> 0 | H10: =SUMIFS(Project_Forecast!$AE$2:$AE$393,Project_Forecast!$E$2:$E$393,$B10,Project_Forecast!$G$2:$G$393,$A10,Project_Forecast!$B$2:$B$393,Controls!$B$30,Project_Forecast!$A$2:$A$393,Controls!$B$7) -> 0 | I10: =SUMIFS(Project_Forecast!$S$2:$S$393,Project_Forecast!$E$2:$E$393,$B10,Project_Forecast!$G$2:$G$393,$A10,Project_Forecast!$B$2:$B$393,Controls!$B$30,Project_Forecast!$A$2:$A$393,Controls!$B$7) -> 0 | J10: =SUMIFS(Project_Forecast!$W$2:$W$393,Project_Forecast!$E$2:$E$393,$B10,Project_Forecast!$G$2:$G$393,$A10,Project_Forecast!$B$2:$B$393,Controls!$B$30,Project_Forecast!$A$2:$A$393,Controls!$B$7) -> 0 | K10: =SUMIFS(Project_Forecast!$Y$2:$Y$393,Project_Forecast!$E$2:$E$393,$B10,Project_Forecast!$G$2:$G$393,$A10,Project_Forecast!$B$2:$B$393,Controls!$B$30,Project_Forecast!$A$2:$A$393,Controls!$B$7) -> 0 | L10: =SUMIFS(Project_Forecast!$AA$2:$AA$393,Project_Forecast!$E$2:$E$393,$B10,Project_Forecast!$G$2:$G$393,$A10,Project_Forecast!$B$2:$B$393,Controls!$B$30,Project_Forecast!$A$2:$A$393,Controls!$B$7) -> 0 | M10: =SUMIFS(Project_Forecast!$AC$2:$AC$393,Project_Forecast!$E$2:$E$393,$B10,Project_Forecast!$G$2:$G$393,$A10,Project_Forecast!$B$2:$B$393,Controls!$B$30,Project_Forecast!$A$2:$A$393,Controls!$B$7) -> 0 | N10: Responsible Sourcing | O10: =SUMIFS(Project_Forecast!$N$2:$N$393,Project_Forecast!$E$2:$E$393,$N10,Project_Forecast!$B$2:$B$393,Controls!$B$30,Project_Forecast!$A$2:$A$393,Controls!$B$7) -> 4090375 | P10: =IFERROR(INDEX(QMR_Inputs!$B$41:$B$47,MATCH($N10,QMR_Inputs!$A$41:$A$47,0)),0) -> 0 | Q10: =O10-P10 -> 4090375
A11: External | B11: Responsible Production | C11: =SUMIFS(MM_Income!$P$5:$P$204,MM_Income!$C$5:$C$204,$B11,MM_Income!$G$5:$G$204,$A11) -> 10453806 | D11: =SUMIFS(Project_Forecast!$N$2:$N$393,Project_Forecast!$E$2:$E$393,$B11,Project_Forecast!$G$2:$G$393,$A11,Project_Forecast!$B$2:$B$393,Controls!$B$30,Project_Forecast!$A$2:$A$393,Controls!$B$7) -> 9760078 | E11: =SUMIFS(Project_Forecast!$N$2:$N$393,Project_Forecast!$E$2:$E$393,$B11,Project_Forecast!$G$2:$G$393,$A11,Project_Forecast!$L$2:$L$393,"Secured",Project_Forecast!$B$2:$B$393,Controls!$B$30,Project_Forecast!$A$2:$A$393,Controls!$B$7) -> 6643820.7 | F11: =CHOOSE(VALUE(MID(Controls!$B$6,2,1)),SUMIFS(Project_Forecast!$W$2:$W$393,Project_Forecast!$E$2:$E$393,$B11,Project_Forecast!$G$2:$G$393,$A11,Project_Forecast!$B$2:$B$393,Controls!$B$30,Project_Forecast!$A$2:$A$393,Controls!$B$7),SUMIFS(Project_Forecast!$Y$2:$Y$393,Project_Forecast!$E$2:$E$393,$B11,Project_Forecast!$G$2:$G$393,$A11,Project_Forecast!$B$2:$B$393,Controls!$B$30,Project_Forecast!$A$2:$A$393,Controls!$B$7),SUMIFS(Project_Forecast!$AA$2:$AA$393,Project_Forecast!$E$2:$E$393,$B11,Project_Forecast!$G$2:$G$393,$A11,Project_Forecast!$B$2:$B$393,Controls!$B$30,Project_Forecast!$A$2:$A$393,Controls!$B$7),SUMIFS(Project_Forecast!$AC$2:$AC$393,Project_Forecast!$E$2:$E$393,$B11,Project_Forecast!$G$2:$G$393,$A11,Project_Forecast!$B$2:$B$393,Controls!$B$30,Project_Forecast!$A$2:$A$393,Controls!$B$7)) -> 1597445.6 | G11: =SUMIFS(Project_Forecast!$AD$2:$AD$393,Project_Forecast!$E$2:$E$393,$B11,Project_Forecast!$G$2:$G$393,$A11,Project_Forecast!$B$2:$B$393,Controls!$B$30,Project_Forecast!$A$2:$A$393,Controls!$B$7) -> 4656235.4 | H11: =SUMIFS(Project_Forecast!$AE$2:$AE$393,Project_Forecast!$E$2:$E$393,$B11,Project_Forecast!$G$2:$G$393,$A11,Project_Forecast!$B$2:$B$393,Controls!$B$30,Project_Forecast!$A$2:$A$393,Controls!$B$7) -> 1865512.9 | I11: =SUMIFS(Project_Forecast!$S$2:$S$393,Project_Forecast!$E$2:$E$393,$B11,Project_Forecast!$G$2:$G$393,$A11,Project_Forecast!$B$2:$B$393,Controls!$B$30,Project_Forecast!$A$2:$A$393,Controls!$B$7) -> 3453417.1 | J11: =SUMIFS(Project_Forecast!$W$2:$W$393,Project_Forecast!$E$2:$E$393,$B11,Project_Forecast!$G$2:$G$393,$A11,Project_Forecast!$B$2:$B$393,Controls!$B$30,Project_Forecast!$A$2:$A$393,Controls!$B$7) -> 3058789.8 | K11: =SUMIFS(Project_Forecast!$Y$2:$Y$393,Project_Forecast!$E$2:$E$393,$B11,Project_Forecast!$G$2:$G$393,$A11,Project_Forecast!$B$2:$B$393,Controls!$B$30,Project_Forecast!$A$2:$A$393,Controls!$B$7) -> 1597445.6 | L11: =SUMIFS(Project_Forecast!$AA$2:$AA$393,Project_Forecast!$E$2:$E$393,$B11,Project_Forecast!$G$2:$G$393,$A11,Project_Forecast!$B$2:$B$393,Controls!$B$30,Project_Forecast!$A$2:$A$393,Controls!$B$7) -> 977984.14 | M11: =SUMIFS(Project_Forecast!$AC$2:$AC$393,Project_Forecast!$E$2:$E$393,$B11,Project_Forecast!$G$2:$G$393,$A11,Project_Forecast!$B$2:$B$393,Controls!$B$30,Project_Forecast!$A$2:$A$393,Controls!$B$7) -> 887528.73 | N11: Responsible Production | O11: =SUMIFS(Project_Forecast!$N$2:$N$393,Project_Forecast!$E$2:$E$393,$N11,Project_Forecast!$B$2:$B$393,Controls!$B$30,Project_Forecast!$A$2:$A$393,Controls!$B$7) -> 9760078 | P11: =IFERROR(INDEX(QMR_Inputs!$B$41:$B$47,MATCH($N11,QMR_Inputs!$A$41:$A$47,0)),0) -> 0 | Q11: =O11-P11 -> 9760078
